<?xml version="1.0"  encoding="UTF-8"?>
<results>
<!-- Project name: 'rubyTrial' - Report dir: 'ju-2014-12-08-16-27-22' - START -->
<!-- Testsuite name: 'AllTests' - START -->
  <!-- Testsuite name: 'testMikeDemo' - START -->
    <testcase external_id="testMikeDemo - Extracted Data" >
    <result>f</result>
    <notes><![CDATA[net.sourceforge.marathon.junit.MarathonAssertion: Application under test aborted - use set_no_fail_on_exit to suppress this error
	Failure: Application under test aborted - use set_no_fail_on_exit to suppress this error
	at System.exit(internal:1)
	at net.sourceforge.marathon.junit.MarathonTestCase.confirmResult(MarathonTestCase.java:213)
	at net.sourceforge.marathon.junit.MarathonTestCase.runTest(MarathonTestCase.java:153)
]]></notes>
    </testcase>
  <!-- Testsuite name: 'testMikeDemo' - END -->
  <!-- Testsuite name: 'testPOC1' - START -->
    <testcase external_id="testPOC1 - Extracted Data" >
    <result>b</result>
    <notes><![CDATA[java.lang.InterruptedException
	at java.lang.Object.wait(Native Method)
	at java.lang.Object.wait(Object.java:503)
	at net.sourceforge.marathon.junit.MarathonTestCase.runTest(MarathonTestCase.java:151)
]]></notes>
    </testcase>
  <!-- Testsuite name: 'testPOC1' - END -->
<!-- Testsuite name: 'AllTests' - END -->
<!-- Project name: 'rubyTrial' - Report dir: 'ju-2014-12-08-16-27-22' - END -->
</results>